Traceback (most recent call last):
  File "/home/yujustin/SSD/DeepUL294Proj/DUL294P/train_gen.py", line 126, in main
    model = torch.load('checkpoints/model.pth')
            ^^^^^^^^^^^^^^^^^^^^^^^^^^^^^^^^^^^
  File "/home/yujustin/anaconda3/envs/fov/lib/python3.11/site-packages/torch/serialization.py", line 998, in load
    with _open_file_like(f, 'rb') as opened_file:
         ^^^^^^^^^^^^^^^^^^^^^^^^
  File "/home/yujustin/anaconda3/envs/fov/lib/python3.11/site-packages/torch/serialization.py", line 445, in _open_file_like
    return _open_file(name_or_buffer, mode)
           ^^^^^^^^^^^^^^^^^^^^^^^^^^^^^^^^
  File "/home/yujustin/anaconda3/envs/fov/lib/python3.11/site-packages/torch/serialization.py", line 426, in __init__
    super().__init__(open(name, mode))
                     ^^^^^^^^^^^^^^^^
FileNotFoundError: [Errno 2] No such file or directory: 'checkpoints/model.pth'
During handling of the above exception, another exception occurred:
Traceback (most recent call last):
  File "/home/yujustin/SSD/DeepUL294Proj/DUL294P/train_gen.py", line 146, in <module>
    main()
  File "/home/yujustin/SSD/DeepUL294Proj/DUL294P/train_gen.py", line 129, in main
    model = FoveatedTransformer()
            ^^^^^^^^^^^^^^^^^^^^^
TypeError: 'module' object is not callable
No model found, creating new model