Training from scratch
Epoch 0
  0%|                                                                                                                                                     | 0/4427 [00:00<?, ?it/s]/home/yujustin/anaconda3/envs/fov/lib/python3.11/site-packages/torch/utils/data/dataloader.py:558: UserWarning: This DataLoader will create 32 worker processes in total. Our suggested max number of worker in current system is 16, which is smaller than what this DataLoader is going to create. Please be aware that excessive worker creation might get DataLoader running slow or even freeze, lower the worker number to avoid potential slowness/freeze if necessary.
  warnings.warn(_create_warning_msg(
  0%|                                                                                                                                                     | 0/4427 [00:16<?, ?it/s]
Traceback (most recent call last):
  File "/home/yujustin/anaconda3/envs/fov/lib/python3.11/site-packages/torch/utils/data/dataloader.py", line 1133, in _try_get_data
    data = self._data_queue.get(timeout=timeout)
           ^^^^^^^^^^^^^^^^^^^^^^^^^^^^^^^^^^^^^
  File "/home/yujustin/anaconda3/envs/fov/lib/python3.11/multiprocessing/queues.py", line 122, in get
    return _ForkingPickler.loads(res)
           ^^^^^^^^^^^^^^^^^^^^^^^^^^
  File "/home/yujustin/anaconda3/envs/fov/lib/python3.11/site-packages/torch/multiprocessing/reductions.py", line 495, in rebuild_storage_fd
    fd = df.detach()
         ^^^^^^^^^^^
  File "/home/yujustin/anaconda3/envs/fov/lib/python3.11/multiprocessing/resource_sharer.py", line 57, in detach
    with _resource_sharer.get_connection(self._id) as conn:
         ^^^^^^^^^^^^^^^^^^^^^^^^^^^^^^^^^^^^^^^^^
  File "/home/yujustin/anaconda3/envs/fov/lib/python3.11/multiprocessing/resource_sharer.py", line 86, in get_connection
    c = Client(address, authkey=process.current_process().authkey)
        ^^^^^^^^^^^^^^^^^^^^^^^^^^^^^^^^^^^^^^^^^^^^^^^^^^^^^^^^^^
  File "/home/yujustin/anaconda3/envs/fov/lib/python3.11/multiprocessing/connection.py", line 524, in Client
    answer_challenge(c, authkey)
  File "/home/yujustin/anaconda3/envs/fov/lib/python3.11/multiprocessing/connection.py", line 772, in answer_challenge
    connection.send_bytes(digest)
  File "/home/yujustin/anaconda3/envs/fov/lib/python3.11/multiprocessing/connection.py", line 200, in send_bytes
    self._send_bytes(m[offset:offset + size])
  File "/home/yujustin/anaconda3/envs/fov/lib/python3.11/multiprocessing/connection.py", line 427, in _send_bytes
    self._send(header + buf)
  File "/home/yujustin/anaconda3/envs/fov/lib/python3.11/multiprocessing/connection.py", line 384, in _send
    n = write(self._handle, buf)
        ^^^^^^^^^^^^^^^^^^^^^^^^
  File "/home/yujustin/anaconda3/envs/fov/lib/python3.11/site-packages/torch/utils/data/_utils/signal_handling.py", line 66, in handler
    _error_if_any_worker_fails()
RuntimeError: DataLoader worker (pid 59481) is killed by signal: Killed.
The above exception was the direct cause of the following exception:
Traceback (most recent call last):
  File "/home/yujustin/SSD/DeepUL294Proj/DUL294P/train_gen.py", line 156, in <module>
    main()
  File "/home/yujustin/SSD/DeepUL294Proj/DUL294P/train_gen.py", line 145, in main
    train_one_epoch()
  File "/home/yujustin/SSD/DeepUL294Proj/DUL294P/train_gen.py", line 130, in train_one_epoch
    for i, batch in enumerate(tqdm(train_loader)):
  File "/home/yujustin/anaconda3/envs/fov/lib/python3.11/site-packages/tqdm/std.py", line 1178, in __iter__
    for obj in iterable:
  File "/home/yujustin/anaconda3/envs/fov/lib/python3.11/site-packages/torch/utils/data/dataloader.py", line 631, in __next__
    data = self._next_data()
           ^^^^^^^^^^^^^^^^^
  File "/home/yujustin/anaconda3/envs/fov/lib/python3.11/site-packages/torch/utils/data/dataloader.py", line 1329, in _next_data
    idx, data = self._get_data()
                ^^^^^^^^^^^^^^^^
  File "/home/yujustin/anaconda3/envs/fov/lib/python3.11/site-packages/torch/utils/data/dataloader.py", line 1295, in _get_data
    success, data = self._try_get_data()
                    ^^^^^^^^^^^^^^^^^^^^
  File "/home/yujustin/anaconda3/envs/fov/lib/python3.11/site-packages/torch/utils/data/dataloader.py", line 1146, in _try_get_data
    raise RuntimeError(f'DataLoader worker (pid(s) {pids_str}) exited unexpectedly') from e
RuntimeError: DataLoader worker (pid(s) 59481) exited unexpectedly