Training from scratch
Epoch 0
/home/yujustin/anaconda3/envs/fov/lib/python3.11/site-packages/torch/utils/data/dataloader.py:558: UserWarning: This DataLoader will create 32 worker processes in total. Our suggested max number of worker in current system is 16, which is smaller than what this DataLoader is going to create. Please be aware that excessive worker creation might get DataLoader running slow or even freeze, lower the worker number to avoid potential slowness/freeze if necessary.
  warnings.warn(_create_warning_msg(
0it [00:01, ?it/s]
Traceback (most recent call last):
  File "/home/yujustin/anaconda3/envs/fov/lib/python3.11/site-packages/torch/utils/data/dataloader.py", line 1133, in _try_get_data
    data = self._data_queue.get(timeout=timeout)
           ^^^^^^^^^^^^^^^^^^^^^^^^^^^^^^^^^^^^^
  File "/home/yujustin/anaconda3/envs/fov/lib/python3.11/multiprocessing/queues.py", line 113, in get
    if not self._poll(timeout):
           ^^^^^^^^^^^^^^^^^^^
  File "/home/yujustin/anaconda3/envs/fov/lib/python3.11/multiprocessing/connection.py", line 257, in poll
    return self._poll(timeout)
           ^^^^^^^^^^^^^^^^^^^
  File "/home/yujustin/anaconda3/envs/fov/lib/python3.11/multiprocessing/connection.py", line 440, in _poll
    r = wait([self], timeout)
        ^^^^^^^^^^^^^^^^^^^^^
  File "/home/yujustin/anaconda3/envs/fov/lib/python3.11/multiprocessing/connection.py", line 947, in wait
    ready = selector.select(timeout)
            ^^^^^^^^^^^^^^^^^^^^^^^^
  File "/home/yujustin/anaconda3/envs/fov/lib/python3.11/selectors.py", line 415, in select
    fd_event_list = self._selector.poll(timeout)
                    ^^^^^^^^^^^^^^^^^^^^^^^^^^^^
  File "/home/yujustin/anaconda3/envs/fov/lib/python3.11/site-packages/torch/utils/data/_utils/signal_handling.py", line 66, in handler
    _error_if_any_worker_fails()
RuntimeError: DataLoader worker (pid 65375) is killed by signal: Killed.
The above exception was the direct cause of the following exception:
Traceback (most recent call last):
  File "/home/yujustin/SSD/DeepUL294Proj/DUL294P/train_gen.py", line 166, in <module>
    main()
  File "/home/yujustin/SSD/DeepUL294Proj/DUL294P/train_gen.py", line 155, in main
    train_one_epoch()
  File "/home/yujustin/SSD/DeepUL294Proj/DUL294P/train_gen.py", line 140, in train_one_epoch
    for i, batch in enumerate(tqdm(zip(trainloader, clip_trainloader))):
  File "/home/yujustin/anaconda3/envs/fov/lib/python3.11/site-packages/tqdm/std.py", line 1178, in __iter__
    for obj in iterable:
  File "/home/yujustin/anaconda3/envs/fov/lib/python3.11/site-packages/torch/utils/data/dataloader.py", line 631, in __next__
    data = self._next_data()
           ^^^^^^^^^^^^^^^^^
  File "/home/yujustin/anaconda3/envs/fov/lib/python3.11/site-packages/torch/utils/data/dataloader.py", line 1329, in _next_data
    idx, data = self._get_data()
                ^^^^^^^^^^^^^^^^
  File "/home/yujustin/anaconda3/envs/fov/lib/python3.11/site-packages/torch/utils/data/dataloader.py", line 1295, in _get_data
    success, data = self._try_get_data()
                    ^^^^^^^^^^^^^^^^^^^^
  File "/home/yujustin/anaconda3/envs/fov/lib/python3.11/site-packages/torch/utils/data/dataloader.py", line 1146, in _try_get_data
    raise RuntimeError(f'DataLoader worker (pid(s) {pids_str}) exited unexpectedly') from e
RuntimeError: DataLoader worker (pid(s) 65375) exited unexpectedly