Training from scratch
Epoch 0
  0%|                                                                                                                                                                  | 0/4427 [00:00<?, ?it/s]/home/yujustin/anaconda3/envs/fov/lib/python3.11/site-packages/torch/utils/data/dataloader.py:558: UserWarning: This DataLoader will create 32 worker processes in total. Our suggested max number of worker in current system is 16, which is smaller than what this DataLoader is going to create. Please be aware that excessive worker creation might get DataLoader running slow or even freeze, lower the worker number to avoid potential slowness/freeze if necessary.
  warnings.warn(_create_warning_msg(
  0%|                                                                                                                                                                  | 0/4427 [00:01<?, ?it/s]
Traceback (most recent call last):
  File "/home/yujustin/SSD/DeepUL294Proj/DUL294P/train_gen.py", line 162, in <module>
    main()
  File "/home/yujustin/SSD/DeepUL294Proj/DUL294P/train_gen.py", line 151, in main
    train_one_epoch()
  File "/home/yujustin/SSD/DeepUL294Proj/DUL294P/train_gen.py", line 107, in train_one_epoch
    for i, batch in enumerate(tqdm(train_loader)):
  File "/home/yujustin/anaconda3/envs/fov/lib/python3.11/site-packages/tqdm/std.py", line 1178, in __iter__
    for obj in iterable:
  File "/home/yujustin/anaconda3/envs/fov/lib/python3.11/site-packages/torch/utils/data/dataloader.py", line 631, in __next__
    data = self._next_data()
           ^^^^^^^^^^^^^^^^^
  File "/home/yujustin/anaconda3/envs/fov/lib/python3.11/site-packages/torch/utils/data/dataloader.py", line 1346, in _next_data
    return self._process_data(data)
           ^^^^^^^^^^^^^^^^^^^^^^^^
  File "/home/yujustin/anaconda3/envs/fov/lib/python3.11/site-packages/torch/utils/data/dataloader.py", line 1372, in _process_data
    data.reraise()
  File "/home/yujustin/anaconda3/envs/fov/lib/python3.11/site-packages/torch/_utils.py", line 722, in reraise
    raise exception
TypeError: Caught TypeError in DataLoader worker process 0.
Original Traceback (most recent call last):
  File "/home/yujustin/anaconda3/envs/fov/lib/python3.11/site-packages/torch/utils/data/_utils/worker.py", line 308, in _worker_loop
    data = fetcher.fetch(index)
           ^^^^^^^^^^^^^^^^^^^^
  File "/home/yujustin/anaconda3/envs/fov/lib/python3.11/site-packages/torch/utils/data/_utils/fetch.py", line 54, in fetch
    return self.collate_fn(data)
           ^^^^^^^^^^^^^^^^^^^^^
  File "/home/yujustin/SSD/DeepUL294Proj/DUL294P/train_gen.py", line 95, in collate_fn
    'image': [pil_to_tensor(x['image']) for x in batch],
             ^^^^^^^^^^^^^^^^^^^^^^^^^^^^^^^^^^^^^^^^^^
  File "/home/yujustin/SSD/DeepUL294Proj/DUL294P/train_gen.py", line 95, in <listcomp>
    'image': [pil_to_tensor(x['image']) for x in batch],
              ^^^^^^^^^^^^^^^^^^^^^^^^^
  File "/home/yujustin/anaconda3/envs/fov/lib/python3.11/site-packages/torchvision/transforms/functional.py", line 199, in pil_to_tensor
    raise TypeError(f"pic should be PIL Image. Got {type(pic)}")
TypeError: pic should be PIL Image. Got <class 'torch.Tensor'>